Workbook

Sheet Instructions
A1: KelliWorks Budget Framework — Developer Reference Guide
A2: CONFIDENTIAL | kelli@kelliworks.com | v1.0
A4: COLOR CODING LEGEND
A5: Blue text | B5: Hardcoded inputs — cells users / Kelli will manually edit
A6: Black text | B6: Calculated formulas — DO NOT hardcode these
A7: Green text | B7: Cross-sheet links pulling from another tab in this workbook
A8: Navy header | B8: Section / column headers
A9: Gold header | B9: Sub-section accent headers
A10: Light blue row | B10: Business budget section rows
A11: Light gold row | B11: Personal budget section rows
A12: Green cell bg | B12: On-track / cleared payment
A13: Red cell bg | B13: Overdue / flagged item
A14: Yellow cell | B14: Needs attention / placeholder to update
A16: WORKBOOK TAB GUIDE
A17: BIZ Budget | B17: All recurring business expenses and subscriptions. One row per vendor. Includes category, amount, due date, payment account, auto-pay flag.
A18: PERSONAL Budget | B18: All recurring personal expenses. Same structure as BIZ Budget. Categories overlap intentionally for cross-comparison in Dashboard.
A19: Dashboard | B19: Combined summary view. Auto-calculates totals from BIZ and PERSONAL tabs. Entrepreneur sees full picture here.
A20: Payment Calendar | B20: Monthly grid showing every bill's due date by week. Color-coded by account. Payment forecast for cash-flow planning.
A21: Forecast | B21: Rolling 3-month forward view. Shows cumulative cash outflows by week. Helps client anticipate cash needs.
A22: DB Schema | B22: Database field definitions for backend developer. Column names, data types, constraints, and notes for Supabase table design.
A24: FIELD DEFINITIONS (applies to BIZ Budget and PERSONAL Budget tabs)
A25: Field Name (DB Column) | B25: Data Type | C25: Required? | D25: Description
A26: vendor_name | B26: Text | C26: Required | D26: The biller/vendor name. Client-editable.
A27: category | B27: Text | C27: Required | D27: Expense category (see Category List below). Enables cross-tab comparison.
A28: subcategory | B28: Text | C28: Optional | D28: More specific grouping within a category.
A29: budget_amount | B29: Currency | C29: Required | D29: Expected monthly cost. Blue input field.
A30: actual_amount | B30: Currency | C30: Formula | D30: Pulled from Plaid transaction match. Auto-updates.
A31: variance_amt | B31: Currency | C31: Formula | D31: =actual - budget. negative = over budget.
A32: variance_pct | B32: Percent | C32: Formula | D32: =variance / budget. color-coded threshold >15%.
A33: frequency | B33: Text | C33: Required | D33: Monthly / Quarterly / Annual / One-Time / Weekly
A34: due_day | B34: Integer | C34: Required | D34: Day of month payment is due (1–31). Drives Payment Calendar.
A35: due_week | B35: Integer | C35: Optional | D35: Week of month (1–4). Used for weekly-pay items.
A36: payment_account | B36: Text | C36: Required | D36: Account the payment draws from (e.g., DISCOVER, OZK, Chase).
... A40: notes | B40: Text | C40: Optional | D40: Free-form notes (e.g., 'PIF annually', 'Cancel by Sept 18').
A43: STANDARD CATEGORY LIST (same names used in both BIZ and PERSONAL tabs for Dashboard comparison)
A44: BUSINESS CATEGORIES | C44: PERSONAL CATEGORIES
A45: Software & Subscriptions | C45: Housing
A46: Insurance | C46: Utilities & Internet
A47: Staffing & Contractors | C47: Food & Groceries
A48: Rent & Facilities | C48: Health & Fitness
...

Sheet BIZ Budget
A1: KelliWorks — KelliWorks — Kelli Lewis Business Budget | 2025–2026
A2: Blue = editable input | Black = formula | Green = cross-sheet link | Status: Active / Cancel / Pending / Seasonal
A3: MONTHLY TOTAL → | D3: =D66 -> 14760.95 | E3: =E66 -> 0 | F3: =F66 -> -14760.95
A4: # | B4: Vendor / Description | C4: Category | D4: Budget Amount ($) | E4: Actual Amount ($) | F4: Variance ($) | G4: Variance (%) | H4: Frequency | I4: Due Day | J4: Due Week | K4: Payment Account | L4: Auto Pay | M4: Status | N4: Notes
A5: Software & Subscriptions
A6: 1 | B6: QuickBooks Online (QBO) | C6: Software & Subscriptions | D6: 453.19 | F6: =IF(E6<>"",E6-D6,"") | G6: =IF(AND(D6<>0,E6<>""),F6/D6,"") | H6: Monthly | I6: 1 | K6: Chase OZK Checking | L6: No | M6: Active
A7: 2 | B7: QuickBooks Subscription | C7: Software & Subscriptions | D7: 120 | F7: =IF(E7<>"",E7-D7,"") | G7: =IF(AND(D7<>0,E7<>""),F7/D7,"") | H7: Monthly | I7: 1 | K7: DISCOVER | L7: Yes | M7: Active
A8: 3 | B8: Google Workspace | C8: Software & Subscriptions | D8: 100 | F8: =IF(E8<>"",E8-D8,"") | G8: =IF(AND(D8<>0,E8<>""),F8/D8,"") | H8: Monthly | I8: 1 | K8: DISCOVER | L8: No | M8: Active
A9: 4 | B9: Asana | C9: Software & Subscriptions | D9: 152.45 | F9: =IF(E9<>"",E9-D9,"") | G9: =IF(AND(D9<>0,E9<>""),F9/D9,"") | H9: Monthly | I9: 5 | K9: DISCOVER | L9: No | M9: Active
A10: 5 | B10: Jace AI | C10: Software & Subscriptions | D10: 20 | F10: =IF(E10<>"",E10-D10,"") | G10: =IF(AND(D10<>0,E10<>""),F10/D10,"") | H10: Monthly | I10: 4 | K10: DISCOVER | L10: No | M10: Active
A11: 6 | B11: Microsoft 365 | C11: Software & Subscriptions | D11: 9.99 | F11: =IF(E11<>"",E11-D11,"") | G11: =IF(AND(D11<>0,E11<>""),F11/D11,"") | H11: Monthly | I11: 7 | K11: DISCOVER | L11: No | M11: Active
A12: 7 | B12: IPFS (Cyber Insurance) | C12: Software & Subscriptions | D12: 142.84 | F12: =IF(E12<>"",E12-D12,"") | G12: =IF(AND(D12<>0,E12<>""),F12/D12,"") | H12: Monthly | I12: 11 | K12: DISCOVER | L12: No | M12: Active
A13: 8 | B13: Slack | C13: Software & Subscriptions | D13: 51.23 | F13: =IF(E13<>"",E13-D13,"") | G13: =IF(AND(D13<>0,E13<>""),F13/D13,"") | H13: Monthly | I13: 15 | K13: DISCOVER | L13: Yes | M13: Active | N13: Delete JT workspace
A14: 9 | B14: Innovative Way | C14: Software & Subscriptions | D14: 100 | F14: =IF(E14<>"",E14-D14,"") | G14: =IF(AND(D14<>0,E14<>""),F14/D14,"") | H14: Monthly | I14: 15 | K14: DISCOVER | L14: Yes | M14: Active
A15: 10 | B15: KlipFolio | C15: Software & Subscriptions | D15: 140 | F15: =IF(E15<>"",E15-D15,"") | G15: =IF(AND(D15<>0,E15<>""),F15/D15,"") | H15: Monthly | I15: 19 | K15: DISCOVER | L15: No | M15: Active
A16: 11 | B16: Adobe | C16: Software & Subscriptions | D16: 21.31 | F16: =IF(E16<>"",E16-D16,"") | G16: =IF(AND(D16<>0,E16<>""),F16/D16,"") | H16: Monthly | I16: 20 | K16: DISCOVER | L16: Yes | M16: Active
A17: 12 | B17: OpenAI ChatGPT | C17: Software & Subscriptions | D17: 60 | F17: =IF(E17<>"",E17-D17,"") | G17: =IF(AND(D17<>0,E17<>""),F17/D17,"") | H17: Monthly | I17: 22 | K17: DISCOVER | L17: Yes | M17: Active
A18: 13 | B18: GHL LeadConnector | C18: Software & Subscriptions | D18: 99 | F18: =IF(E18<>"",E18-D18,"") | G18: =IF(AND(D18<>0,E18<>""),F18/D18,"") | H18: Monthly | K18: DISCOVER | L18: No | M18: Active
A19: 14 | B19: Keap CRM | C19: Software & Subscriptions | D19: 269 | F19: =IF(E19<>"",E19-D19,"") | G19: =IF(AND(D19<>0,E19<>""),F19/D19,"") | H19: Monthly | K19: DISCOVER | L19: No | M19: Active
A20: 15 | B20: Canva | C20: Software & Subscriptions | D20: 21.99 | F20: =IF(E20<>"",E20-D20,"") | G20: =IF(AND(D20<>0,E20<>""),F20/D20,"") | H20: Monthly | I20: 21 | K20: DISCOVER | L20: No | M20: Active | N20: PIF annually 12/5 — $120
A21: 16 | B21: Bill.com | C21: Software & Subscriptions | D21: 25 | F21: =IF(E21<>"",E21-D21,"") | G21: =IF(AND(D21<>0,E21<>""),F21/D21,"") | H21: Monthly | K21: DISCOVER | L21: No | M21: Active
A22: 17 | B22: Fathom | C22: Software & Subscriptions | D22: 19.95 | F22: =IF(E22<>"",E22-D22,"") | G22: =IF(AND(D22<>0,E22<>""),F22/D22,"") | H22: Monthly | K22: DISCOVER | L22: No | M22: Active
A23: 18 | B23: EverHour | C23: Software & Subscriptions | D23: 50 | F23: =IF(E23<>"",E23-D23,"") | G23: =IF(AND(D23<>0,E23<>""),F23/D23,"") | H23: Monthly | K23: DISCOVER | L23: No | M23: Active
A24: 19 | B24: Zoom | C24: Software & Subscriptions | D24: 36.23 | F24: =IF(E24<>"",E24-D24,"") | G24: =IF(AND(D24<>0,E24<>""),F24/D24,"") | H24: Monthly | K24: DISCOVER | L24: No | M24: Active
A25: 20 | B25: Dropbox (Business) | C25: Software & Subscriptions | D25: 72 | F25: =IF(E25<>"",E25-D25,"") | G25: =IF(AND(D25<>0,E25<>""),F25/D25,"") | H25: Monthly | K25: DISCOVER | L25: No | M25: Active | N25: Verify due date
A26: 21 | B26: Dropbox (Personal) | C26: Software & Subscriptions | D26: 20 | F26: =IF(E26<>"",E26-D26,"") | G26: =IF(AND(D26<>0,E26<>""),F26/D26,"") | H26: Monthly | K26: DISCOVER | L26: No | M26: Active
A27: 22 | B27: 1Password | C27: Software & Subscriptions | D27: 19.95 | F27: =IF(E27<>"",E27-D27,"") | G27: =IF(AND(D27<>0,E27<>""),F27/D27,"") | H27: Monthly | K27: DISCOVER | L27: No | M27: Active
A28: 23 | B28: Voice Inplu | C28: Software & Subscriptions | D28: 9.99 | F28: =IF(E28<>"",E28-D28,"") | G28: =IF(AND(D28<>0,E28<>""),F28/D28,"") | H28: Monthly | L28: No | M28: Active
A29: 24 | B29: Gamma | C29: Software & Subscriptions | D29: 20 | F29: =IF(E29<>"",E29-D29,"") | G29: =IF(AND(D29<>0,E29<>""),F29/D29,"") | H29: Monthly | L29: No | M29: Cancel | N29: Cancel ASAP
A30: 25 | B30: Greenlight | C30: Software & Subscriptions | D30: 9.99 | F30: =IF(E30<>"",E30-D30,"") | G30: =IF(AND(D30<>0,E30<>""),F30/D30,"") | H30: Monthly | L30: No | M30: Cancel | N30: Cancel ASAP
A31: 26 | B31: Motion | C31: Software & Subscriptions | D31: 34 | F31: =IF(E31<>"",E31-D31,"") | G31: =IF(AND(D31<>0,E31<>""),F31/D31,"") | H31: Monthly | L31: Yes | M31: Cancel | N31: Cancel by Sept 18, 2025
A32: 27 | B32: Loom | C32: Software & Subscriptions | D32: 24 | F32: =IF(E32<>"",E32-D32,"") | G32: =IF(AND(D32<>0,E32<>""),F32/D32,"") | H32: Monthly | I32: 15 | K32: Wells Fargo Business | L32: Yes | M32: Active
A33: 28 | B33: Link Tree | C33: Software & Subscriptions | D33: 9 | F33: =IF(E33<>"",E33-D33,"") | G33: =IF(AND(D33<>0,E33<>""),F33/D33,"") | H33: Monthly | I33: 15 | L33: No | M33: Active
A34: 29 | B34: Jace AI (confirm) | C34: Software & Subscriptions | D34: 20 | F34: =IF(E34<>"",E34-D34,"") | G34: =IF(AND(D34<>0,E34<>""),F34/D34,"") | H34: Monthly | K34: DISCOVER | L34: No | M34: Active
A35: Insurance
A36: 30 | B36: HISCOX Liability Policy | C36: Insurance | D36: 177 | F36: =IF(E36<>"",E36-D36,"") | G36: =IF(AND(D36<>0,E36<>""),F36/D36,"") | H36: Monthly | I36: 30 | K36: BIZ OZK Checking | L36: Yes | M36: Active
A37: 31 | B37: IPFS (Cyber Insurance) | C37: Insurance | D37: 142.84 | F37: =IF(E37<>"",E37-D37,"") | G37: =IF(AND(D37<>0,E37<>""),F37/D37,"") | H37: Monthly | I37: 11 | K37: DISCOVER | L37: No | M37: Active | N37: Also listed under Software
A38: Staffing & Contractors
A39: 32 | B39: Bookkeeper | C39: Staffing & Contractors | D39: 2400 | F39: =IF(E39<>"",E39-D39,"") | G39: =IF(AND(D39<>0,E39<>""),F39/D39,"") | H39: Monthly | L39: No | M39: Active | N39: Kearns / Heartland debt
A40: 33 | B40: EA — Tim | C40: Staffing & Contractors | D40: 1000 | F40: =IF(E40<>"",E40-D40,"") | G40: =IF(AND(D40<>0,E40<>""),F40/D40,"") | H40: Monthly | L40: No | M40: Active
...

Sheet PERSONAL Budget
A1: KelliWorks — KelliWorks — Kelli Lewis Personal Budget | 2025–2026
A2: Blue = editable input | Black = formula | Green = cross-sheet link | Status: Active / Cancel / Pending / Seasonal
A3: MONTHLY TOTAL → | D3: =D40 -> 14770.25 | E3: =E40 -> 0 | F3: =F40 -> -14770.25
A4: # | B4: Vendor / Description | C4: Category | D4: Budget Amount ($) | E4: Actual Amount ($) | F4: Variance ($) | G4: Variance (%) | H4: Frequency | I4: Due Day | J4: Due Week | K4: Payment Account | L4: Auto Pay | M4: Status | N4: Notes
A5: Housing
A6: 1 | B6: Lantower Riverslanding (Rent) | C6: Housing | D6: 8700 | F6: =IF(E6<>"",E6-D6,"") | G6: =IF(AND(D6<>0,E6<>""),F6/D6,"") | H6: Monthly | I6: 1 | J6: 1 | L6: No | M6: Active | N6: Week 1 due
A7: 2 | B7: FPL (Electric) | C7: Utilities & Internet | D7: 300 | F7: =IF(E7<>"",E7-D7,"") | G7: =IF(AND(D7<>0,E7<>""),F7/D7,"") | H7: Monthly | J7: 1 | L7: No | M7: Active | N7: Week 1 due
A8: 3 | B8: Home Internet (AT&T) | C8: Utilities & Internet | D8: 165.78 | F8: =IF(E8<>"",E8-D8,"") | G8: =IF(AND(D8<>0,E8<>""),F8/D8,"") | H8: Monthly | I8: 10 | K8: FIRST DIGITAL | L8: No | M8: Active
A9: 4 | B9: Storage | C9: Housing | D9: 220 | F9: =IF(E9<>"",E9-D9,"") | G9: =IF(AND(D9<>0,E9<>""),F9/D9,"") | H9: Monthly | L9: No | M9: Active | N9: Verify due date
A10: Food & Groceries
A11: 5 | B11: Publix / Amazon (Groceries) | C11: Food & Groceries | D11: 200 | F11: =IF(E11<>"",E11-D11,"") | G11: =IF(AND(D11<>0,E11<>""),F11/D11,"") | H11: Weekly | L11: No | M11: Active | N11: ~$200/week × 4
A12: 6 | B12: Dining Out / Eating Out | C12: Food & Groceries | D12: 125 | F12: =IF(E12<>"",E12-D12,"") | G12: =IF(AND(D12<>0,E12<>""),F12/D12,"") | H12: Weekly | L12: No | M12: Active | N12: ~$125/week × 4
A13: Health & Fitness
A14: 7 | B14: Equinox | C14: Health & Fitness | D14: 379 | F14: =IF(E14<>"",E14-D14,"") | G14: =IF(AND(D14<>0,E14<>""),F14/D14,"") | H14: Monthly | J14: 3 | K14: CHASE DEBIT | L14: No | M14: Active | N14: Week 3 — $365 alt amount seen
A15: 8 | B15: Peloton | C15: Health & Fitness | D15: 49 | F15: =IF(E15<>"",E15-D15,"") | G15: =IF(AND(D15<>0,E15<>""),F15/D15,"") | H15: Monthly | J15: 1 | K15: CHASE DEBIT | L15: No | M15: Active | N15: Week 1 — $50 alt amount seen
A16: 9 | B16: Aspen Dental | C16: Health & Fitness | D16: 153 | F16: =IF(E16<>"",E16-D16,"") | G16: =IF(AND(D16<>0,E16<>""),F16/D16,"") | H16: Monthly | K16: Chase Checking | L16: No | M16: Active | N16: HFD Dental Finance $150/wk3
A17: Insurance
A18: 10 | B18: Life Insurance Policy | C18: Insurance | D18: 310 | F18: =IF(E18<>"",E18-D18,"") | G18: =IF(AND(D18<>0,E18<>""),F18/D18,"") | H18: Monthly | I18: 27 | K18: Wells Fargo Business | L18: Yes | M18: Active
A19: 11 | B19: Disability Insurance | C19: Insurance | D19: 300 | F19: =IF(E19<>"",E19-D19,"") | G19: =IF(AND(D19<>0,E19<>""),F19/D19,"") | H19: Monthly | L19: No | M19: Active
A20: 12 | B20: Identity IQ | C20: Insurance | D20: 30.47 | F20: =IF(E20<>"",E20-D20,"") | G20: =IF(AND(D20<>0,E20<>""),F20/D20,"") | H20: Monthly | I20: 1 | K20: FIRST DIGITAL | L20: No | M20: Active
A21: Children
A22: 13 | B22: Children Expenses (Misc) | C22: Children | D22: 235 | F22: =IF(E22<>"",E22-D22,"") | G22: =IF(AND(D22<>0,E22<>""),F22/D22,"") | H22: Weekly | L22: No | M22: Active | N22: ~$235/week
A23: 14 | B23: Pediatric Dentist — Prince (Braces) | C23: Children | D23: 183 | F23: =IF(E23<>"",E23-D23,"") | G23: =IF(AND(D23<>0,E23<>""),F23/D23,"") | H23: Monthly | J23: 4 | L23: No | M23: Active | N23: Week 4
A24: Savings & Investments
A25: 15 | B25: NorthWestern Investment | C25: Savings & Investments | D25: 375 | F25: =IF(E25<>"",E25-D25,"") | G25: =IF(AND(D25<>0,E25<>""),F25/D25,"") | H25: Weekly | K25: NWM Savings | L25: No | M25: Active | N25: $375/week — $1,500/mo total
A26: 16 | B26: Savings Transfer | C26: Savings & Investments | D26: 1500 | F26: =IF(E26<>"",E26-D26,"") | G26: =IF(AND(D26<>0,E26<>""),F26/D26,"") | H26: Monthly | K26: AMEX / Savings | L26: No | M26: Active | N26: $375/week target
A27: 17 | B27: Acorn Investing | C27: Savings & Investments | D27: 100 | F27: =IF(E27<>"",E27-D27,"") | G27: =IF(AND(D27<>0,E27<>""),F27/D27,"") | H27: Monthly | K27: DISCOVER | L27: No | M27: Active
A28: Transportation
A29: 18 | B29: Jorge (Driver) | C29: Transportation | D29: 500 | F29: =IF(E29<>"",E29-D29,"") | G29: =IF(AND(D29<>0,E29<>""),F29/D29,"") | H29: Weekly | L29: No | M29: Active | N29: $500/week × 4 = $2,000/mo
A30: Personal Care
A31: 19 | B31: Personal Care (Misc) | C31: Personal Care | D31: 185 | F31: =IF(E31<>"",E31-D31,"") | G31: =IF(AND(D31<>0,E31<>""),F31/D31,"") | H31: Weekly | L31: No | M31: Active | N31: ~$185/week
A32: 20 | B32: Amela G (Cleaning) | C32: Personal Care | D32: 500 | F32: =IF(E32<>"",E32-D32,"") | G32: =IF(AND(D32<>0,E32<>""),F32/D32,"") | H32: Weekly | L32: No | M32: Active | N32: $500/week — confirm frequency
A33: Entertainment & Memberships
A34: 21 | B34: Netflix | C34: Entertainment | D34: 27 | F34: =IF(E34<>"",E34-D34,"") | G34: =IF(AND(D34<>0,E34<>""),F34/D34,"") | H34: Monthly | L34: No | M34: Active
A35: 22 | B35: Amazon Prime | C35: Entertainment | D35: 38 | F35: =IF(E35<>"",E35-D35,"") | G35: =IF(AND(D35<>0,E35<>""),F35/D35,"") | H35: Monthly | K35: CHASE DEBIT | L35: No | M35: Active
A36: 23 | B36: Ancestry | C36: Entertainment | D36: 25 | F36: =IF(E36<>"",E36-D36,"") | G36: =IF(AND(D36<>0,E36<>""),F36/D36,"") | H36: Monthly | K36: CHASE DEBIT | L36: No | M36: Active
A37: Charity
A38: 24 | B38: Charity (Misc) | C38: Charity | D38: 170 | F38: =IF(E38<>"",E38-D38,"") | G38: =IF(AND(D38<>0,E38<>""),F38/D38,"") | H38: Monthly | L38: No | M38: Active
A40: GRAND TOTAL | D40: =SUMIF(D5:D38,">0") -> 14770.25 | E40: =SUMIF(E5:E38,">0") -> 0 | F40: =IF(E40<>"",E40-D40,"") -> -14770.25

Sheet Dashboard
A1: KelliWorks — Financial Dashboard | Business + Personal Combined View
A2: Auto-calculated from BIZ Budget and PERSONAL Budget tabs
A4: BIZ Monthly Budget | B4: BIZ Actual (MTD) | C4: PERSONAL Monthly Budget | D4: PERSONAL Actual (MTD) | E4: COMBINED Budget | F4: COMBINED Actual (MTD)
A5: ='BIZ Budget'!D66 -> 14760.95 | B5: ='BIZ Budget'!E66 -> 0 | C5: ='PERSONAL Budget'!D40 -> 14770.25 | D5: ='PERSONAL Budget'!E40 -> 0 | E5: ='BIZ Budget'!D66+'PERSONAL Budget'!D40 -> 29531.2 | F5: ='BIZ Budget'!E66+'PERSONAL Budget'!E40 -> 0
A7: SPENDING BY CATEGORY — Business vs. Personal
A8: Category | B8: BIZ Budget ($) | C8: BIZ Actual ($) | D8: BIZ Variance | E8: PERSONAL Budget ($) | F8: PERSONAL Actual ($) | G8: PERSONAL Variance | H8: COMBINED Total
A9: Software & Subscriptions | B9: — | C9: — | D9: — | E9: — | F9: — | G9: — | H9: —
A10: Insurance | B10: — | C10: — | D10: — | E10: — | F10: — | G10: — | H10: —
A11: Staffing & Contractors | B11: — | C11: — | D11: — | E11: — | F11: — | G11: — | H11: —
A12: Rent & Facilities | B12: — | C12: — | D12: — | E12: — | F12: — | G12: — | H12: —
A13: Marketing & Advertising | B13: — | C13: — | D13: — | E13: — | F13: — | G13: — | H13: —
A14: Accounting & Finance | B14: — | C14: — | D14: — | E14: — | F14: — | G14: — | H14: —
A15: Communications | B15: — | C15: — | D15: — | E15: — | F15: — | G15: — | H15: —
A16: Banking & Payments | B16: — | C16: — | D16: — | E16: — | F16: — | G16: — | H16: —
A17: Health & Wellness | B17: — | C17: — | D17: — | E17: — | F17: — | G17: — | H17: —
A18: Storage | B18: — | C18: — | D18: — | E18: — | F18: — | G18: — | H18: —
A19: Savings & Investments | B19: — | C19: — | D19: — | E19: — | F19: — | G19: — | H19: —
A20: Miscellaneous | B20: — | C20: — | D20: — | E20: — | F20: — | G20: — | H20: —
A22: ℹ Category totals will auto-populate when SUMIF formulas are linked to BIZ Budget and PERSONAL Budget tabs by the developer.
A24: PAYMENTS BY ACCOUNT — Monthly Summary
A25: Payment Account | B25: # of Bills | C25: Total Budget ($) | D25: Auto-Pay Bills
A26: DISCOVER | B26: — | C26: — | D26: —
A27: OZK Business | B27: — | C27: — | D27: —
A28: Wells Fargo Business | B28: — | C28: — | D28: —
A29: Chase Checking | B29: — | C29: — | D29: —
A30: Chase Debit | B30: — | C30: — | D30: —
A31: First Digital | B31: — | C31: — | D31: —
A32: Other | B32: — | C32: — | D32: —

Sheet Payment Calendar
A1: KelliWorks — Monthly Payment Calendar
A2: Bills organized by due date | Blue = manual payment required | Green = Auto Pay | Orange = Quarterly
A3: Vendor / Description | B3: Category | C3: Budget Amount | D3: Account | E3: Auto Pay | F3: Notes
A4: 📅 WEEK 1 (Days 1–7)
A5: QuickBooks Online (QBO) [Day 1] | B5: Software | C5: 453.19 | D5: OZK Checking | E5: No
A6: QuickBooks Subscription [Day 1] | B6: Software | C6: 120 | D6: DISCOVER | E6: Yes
A7: Google Workspace [Day 1] | B7: Software | C7: 100 | D7: DISCOVER | E7: No
A8: Yelp Subscription [Day 1] | B8: Marketing | C8: 200 | D8: Wells Fargo Biz | E8: No
A9: Lantower Riverslanding (Rent) [Day 1] | B9: Housing | C9: 8700 | E9: No | F9: Week 1
A10: Identity IQ [Day 1] | B10: Insurance | C10: 30.47 | D10: FIRST DIGITAL | E10: No
A11: Jace AI [Day 4] | B11: Software | C11: 20 | D11: DISCOVER | E11: No
A12: Asana [Day 5] | B12: Software | C12: 152.45 | D12: DISCOVER | E12: No
A13: Microsoft 365 [Day 7] | B13: Software | C13: 9.99 | D13: DISCOVER | E13: No
A14: Miami Made [Day 7] | B14: Marketing | C14: 65 | E14: No
A15: Jorge (Driver) [] | B15: Transportation | C15: 500 | E15: No | F15: Weekly ~$500
A16: NorthWestern Investment [] | B16: Savings | C16: 375 | D16: NWM | E16: No | F16: Weekly ~$375
A17: WEEK 1 (Days 1–7) SUBTOTAL | C17: =SUM(C5:C16) -> 10726.1
A19: 📅 WEEK 2 (Days 8–14)
A20: Home Internet (AT&T) [Day 10] | B20: Utilities | C20: 165.78 | D20: FIRST DIGITAL | E20: No
A21: IPFS (Cyber Insurance) [Day 11] | B21: Insurance | C21: 142.84 | D21: DISCOVER | E21: No
A22: WEEK 2 (Days 8–14) SUBTOTAL | C22: =SUM(C20:C21) -> 308.62
A24: 📅 WEEK 3 (Days 15–21)
A25: Slack [Day 15] | B25: Software | C25: 51.23 | D25: DISCOVER | E25: Yes
A26: Innovative Way [Day 15] | B26: Software | C26: 100 | D26: DISCOVER | E26: Yes
A27: Keeper Security [Day 15] | B27: Professional | C27: 500 | D27: Wells Fargo Biz | E27: No
A28: Loom [Day 15] | B28: Software | C28: 24 | D28: Wells Fargo Biz | E28: Yes
A29: Link Tree [Day 15] | B29: Software | C29: 9 | E29: No
A30: KlipFolio [Day 19] | B30: Software | C30: 140 | D30: DISCOVER | E30: No
A31: Wix (Site 1) [Day 19] | B31: Marketing | C31: 43 | D31: Wells Fargo Biz | E31: Yes
A32: Adobe [Day 20] | B32: Software | C32: 21.31 | D32: DISCOVER | E32: Yes
A33: Wix (Site 2) [Day 20] | B33: Marketing | C33: 24 | D33: Wells Fargo Biz | E33: Yes
A34: SoHo House (Quarterly) [Day 20] | B34: Memberships | C34: 1400 | D34: Wells Fargo Biz | E34: Yes | F34: Quarterly — Sept/Dec/Mar/Jun
A35: Canva [Day 21] | B35: Software | C35: 21.99 | D35: DISCOVER | E35: No
A36: WEEK 3 (Days 15–21) SUBTOTAL | C36: =SUM(C25:C35) -> 2334.53
A38: 📅 WEEK 4 (Days 22–31)
A39: OpenAI ChatGPT [Day 22] | B39: Software | C39: 60 | D39: DISCOVER | E39: Yes
A40: Life Insurance Policy [Day 27] | B40: Insurance | C40: 310 | D40: Wells Fargo Biz | E40: Yes
A41: HISCOX Liability Policy [Day 30] | B41: Insurance | C41: 177 | D41: BIZ OZK | E41: Yes
A42: WEEK 4 (Days 22–31) SUBTOTAL | C42: =SUM(C39:C41) -> 547

Sheet Forecast
A1: KelliWorks — 3-Month Rolling Payment Forecast
A2: Forward-looking cash outflow projection | Blue = editable | Quarterly bills spread across applicable months
A4: Vendor / Description | B4: Category | C4: Month 1 (Current) | E4: Month 2 | G4: Month 3 | I4: Freq. | J4: Notes
C5: Budget ($) | D5: Projected ($) | E5: Budget ($) | F5: Projected ($) | G5: Budget ($) | H5: Projected ($)
A6: QuickBooks Online (QBO) | B6: Software & Subscriptions | C6: 453.19 | E6: 453.19 | G6: 453.19 | I6: Monthly
A7: QuickBooks Subscription | B7: Software & Subscriptions | C7: 120 | E7: 120 | G7: 120 | I7: Monthly
A8: Google Workspace | B8: Software & Subscriptions | C8: 100 | E8: 100 | G8: 100 | I8: Monthly
A9: Asana | B9: Software & Subscriptions | C9: 152.45 | E9: 152.45 | G9: 152.45 | I9: Monthly
A10: Jace AI | B10: Software & Subscriptions | C10: 20 | E10: 20 | G10: 20 | I10: Monthly
A11: Microsoft 365 | B11: Software & Subscriptions | C11: 9.99 | E11: 9.99 | G11: 9.99 | I11: Monthly
A12: IPFS (Cyber Insurance) | B12: Software & Subscriptions | C12: 142.84 | E12: 142.84 | G12: 142.84 | I12: Monthly
A13: Slack | B13: Software & Subscriptions | C13: 51.23 | E13: 51.23 | G13: 51.23 | I13: Monthly | J13: Delete JT workspace
A14: Innovative Way | B14: Software & Subscriptions | C14: 100 | E14: 100 | G14: 100 | I14: Monthly
A15: KlipFolio | B15: Software & Subscriptions | C15: 140 | E15: 140 | G15: 140 | I15: Monthly
A16: Adobe | B16: Software & Subscriptions | C16: 21.31 | E16: 21.31 | G16: 21.31 | I16: Monthly
A17: OpenAI ChatGPT | B17: Software & Subscriptions | C17: 60 | E17: 60 | G17: 60 | I17: Monthly
A18: GHL LeadConnector | B18: Software & Subscriptions | C18: 99 | E18: 99 | G18: 99 | I18: Monthly
A19: Keap CRM | B19: Software & Subscriptions | C19: 269 | E19: 269 | G19: 269 | I19: Monthly
A20: Canva | B20: Software & Subscriptions | C20: 21.99 | E20: 21.99 | G20: 21.99 | I20: Monthly | J20: PIF annually 12/5 — $120
A21: Bill.com | B21: Software & Subscriptions | C21: 25 | E21: 25 | G21: 25 | I21: Monthly
A22: Fathom | B22: Software & Subscriptions | C22: 19.95 | E22: 19.95 | G22: 19.95 | I22: Monthly
A23: EverHour | B23: Software & Subscriptions | C23: 50 | E23: 50 | G23: 50 | I23: Monthly
A24: Zoom | B24: Software & Subscriptions | C24: 36.23 | E24: 36.23 | G24: 36.23 | I24: Monthly
A25: Dropbox (Business) | B25: Software & Subscriptions | C25: 72 | E25: 72 | G25: 72 | I25: Monthly | J25: Verify due date
A26: Dropbox (Personal) | B26: Software & Subscriptions | C26: 20 | E26: 20 | G26: 20 | I26: Monthly
A27: 1Password | B27: Software & Subscriptions | C27: 19.95 | E27: 19.95 | G27: 19.95 | I27: Monthly
A28: Voice Inplu | B28: Software & Subscriptions | C28: 9.99 | E28: 9.99 | G28: 9.99 | I28: Monthly
A29: Gamma | B29: Software & Subscriptions | C29: 20 | E29: 20 | G29: 20 | I29: Monthly | J29: Cancel ASAP
A30: Greenlight | B30: Software & Subscriptions | C30: 9.99 | E30: 9.99 | G30: 9.99 | I30: Monthly | J30: Cancel ASAP
A31: Motion | B31: Software & Subscriptions | C31: 34 | E31: 34 | G31: 34 | I31: Monthly | J31: Cancel by Sept 18, 2025
A32: Loom | B32: Software & Subscriptions | C32: 24 | E32: 24 | G32: 24 | I32: Monthly
A33: Link Tree | B33: Software & Subscriptions | C33: 9 | E33: 9 | G33: 9 | I33: Monthly
A34: Jace AI (confirm) | B34: Software & Subscriptions | C34: 20 | E34: 20 | G34: 20 | I34: Monthly
A35: HISCOX Liability Policy | B35: Insurance | C35: 177 | E35: 177 | G35: 177 | I35: Monthly
A36: IPFS (Cyber Insurance) | B36: Insurance | C36: 142.84 | E36: 142.84 | G36: 142.84 | I36: Monthly | J36: Also listed under Software
A37: Bookkeeper | B37: Staffing & Contractors | C37: 2400 | E37: 2400 | G37: 2400 | I37: Monthly | J37: Kearns / Heartland debt
A38: EA — Tim | B38: Staffing & Contractors | C38: 1000 | E38: 1000 | G38: 1000 | I38: Monthly
A39: Intern | B39: Staffing & Contractors | C39: 500 | E39: 500 | G39: 500 | I39: Monthly
A40: Will / Precise | B40: Staffing & Contractors | C40: 500 | E40: 500 | G40: 500 | I40: Monthly | J40: $50,000 outstanding balance
A41: Office Rent (New) | B41: Rent & Facilities | C41: 2500 | E41: 2500 | G41: 2500 | I41: Monthly | J41: $2,300 possible alt amount
...

Sheet DB Schema
A1: KelliWorks — Supabase Database Schema Reference
A2: For developer use only — maps Excel fields to PostgreSQL table columns
A4: TABLE: bills (recurring_bills)
A5: Column Name | B5: Data Type | C5: Constraints | D5: Description
A6: id | B6: uuid | C6: PRIMARY KEY | D6: Auto-generated. DEFAULT gen_random_uuid()
A7: client_id | B7: uuid | C7: FK → clients | D7: References clients.id. Row-level security enforces isolation.
A8: vendor_name | B8: text | C8: NOT NULL | D8: Biller name. Client-editable.
A9: category | B9: text | C9: NOT NULL | D9: Enum: see category list in Instructions tab.
A10: subcategory | B10: text | C10: NULLABLE
A11: bill_type | B11: text | C11: NOT NULL | D11: Enum: 'business' | 'personal'
A12: budget_amount | B12: numeric | C12: NOT NULL | D12: Expected monthly cost in USD.
A13: actual_amount | B13: numeric | C13: NULLABLE | D13: Populated by Plaid match. NULL until matched.
A14: frequency | B14: text | C14: NOT NULL | D14: Enum: 'monthly' | 'quarterly' | 'annual' | 'weekly' | 'one_time'
A15: due_day | B15: smallint | C15: NULLABLE | D15: Day of month (1–31). NULL for weekly items.
A16: due_week | B16: smallint | C16: NULLABLE | D16: Week of month (1–4). Used for weekly items.
A17: payment_account | B17: text | C17: NULLABLE | D17: Account nickname. e.g. DISCOVER, OZK, Chase.
A18: auto_pay | B18: boolean | C18: NOT NULL DEFAULT false | D18: True = ACH/auto-charge.
A19: status | B19: text | C19: NOT NULL DEFAULT 'active' | D19: Enum: 'active' | 'cancelled' | 'pending' | 'seasonal'
A20: alert_threshold | B20: numeric | C20: NULLABLE DEFAULT 0.15 | D20: Variance % threshold for yellow alert. Default 15%.
A21: notes | B21: text | C21: NULLABLE | D21: Free-form advisor notes.
A22: plaid_match_id | B22: text | C22: NULLABLE | D22: Plaid transaction ID that cleared this bill.
A23: cleared_at | B23: timestamptz | C23: NULLABLE | D23: Timestamp when Plaid confirmed payment cleared.
A24: created_at | B24: timestamptz | C24: NOT NULL DEFAULT now()
A25: updated_at | B25: timestamptz | C25: NOT NULL DEFAULT now()
A27: TABLE: clients
A28: Column Name | B28: Data Type | C28: Constraints | D28: Description
A29: id | B29: uuid | C29: PRIMARY KEY
A30: advisor_id | B30: uuid | C30: FK → users | D30: Kelli or advisor who manages this client.
A31: full_name | B31: text | C31: NOT NULL
A32: email | B32: text | C32: UNIQUE NOT NULL
A33: tier | B33: text | C33: NOT NULL | D33: Enum: 'standard' | 'upgraded'
A34: onboarding_complete | B34: boolean | C34: NOT NULL DEFAULT false
A35: created_at | B35: timestamptz | C35: NOT NULL DEFAULT now()
A37: TABLE: payment_alerts
A38: Column Name | B38: Data Type | C38: Constraints | D38: Description
A39: id | B39: uuid | C39: PRIMARY KEY
A40: client_id | B40: uuid | C40: FK → clients
A41: bill_id | B41: uuid | C41: FK → bills
A42: alert_type | B42: text | C42: NOT NULL | D42: Enum: 'yellow' | 'red'
A43: reason | B43: text | C43: NOT NULL | D43: e.g. 'overdue' | 'amount_fluctuation' | 'insufficient_funds'
...
